Workbook

Sheet Cover Page
B2: Hospital Nursing Labor Cost & Staffing Optimization Model Overtime, Agency Dependency, Turnover Cost & Scenario-Based Budgeting
C7: Content
C10: Output - Rollup
C11: Model
C12: Inputs & Scenarios

Sheet Output - Rollup
B2: Summary
B6: Unit | C6: Total Labor Cost | D6: Agency Cost | E6: OT% | F6: Agency % | G6: Turnover & Vacancy | H6: Total Cost Incl Turnover | I6: Service Volume | J6: Cost/Unit | L6: Model Control
B7: Med-Surg | C7: =Model!C13 -> 10226179 | D7: =Model!C16 -> 1702944 | E7: =Model!C14 -> 0 | F7: =Model!C15 -> 0.12 | G7: =Model!C17 -> 511410 | H7: =Model!C18 -> 10737589 | I7: =Model!C19 -> 26280 | J7: =Model!C20 -> 389.124 | L7: Scenario
B8: ICU | C8: =Model!G13 -> 8202735.3 | D8: =Model!G16 -> 1685205 | E8: =Model!G14 -> 0 | F8: =Model!G15 -> 0.15 | G8: =Model!G17 -> 421410 | H8: =Model!G18 -> 8624145.3 | I8: =Model!G19 -> 10402.5 | J8: =Model!G20 -> 788.535
B9: ED | C9: =Model!K13 -> 3889091.3 | D9: =Model!K16 -> 544500 | E9: =Model!K14 -> 0 | F9: =Model!K15 -> 0.1 | G9: =Model!K17 -> 211410 | H9: =Model!K18 -> 4100501.3 | I9: =Model!K19 -> 55000 | J9: =Model!K20 -> 70.71075
B11: Total | C11: =SUM(C7:C10) -> 22318005 | D11: =SUM(D7:D10) -> 3932649 | G11: =SUM(G7:G10) -> 1144230 | H11: =SUM(H7:H10) -> 23462235 | I11: =SUM(I7:I9) -> 91682.5

Sheet Model
B2: Mutli-Unit Nursing Salary Model
F6: Model Control
F7: Scenario
B9: Med - Surg Unit | F9: ICU Unit | J9: ED Unit
B12: Outputs | F12: Outputs | J12: Outputs
B13: Total Labor Cost (Incl Benefits) | C13: =C63 -> 10226179 | F13: Total Labor Cost (Incl Benefits) | G13: =G63 -> 8202735.3 | J13: Total Labor Cost (Incl Benefits) | K13: =K63 -> 3889091.3
B14: OT% | C14: =C49 -> 0 | F14: OT% | G14: =G49 -> 0 | J14: OT% | K14: =K49 -> 0
B15: Agency % | C15: =C50 -> 0.12 | F15: Agency % | G15: =G50 -> 0.15 | J15: Agency % | K15: =K50 -> 0.1
B16: Agency Cost | C16: =C61 -> 1702944 | F16: Agency Cost | G16: =G61 -> 1685205 | J16: Agency Cost | K16: =K61 -> 544500
B17: Turnover & Vacancy Cost | C17: =C79 -> 511410 | F17: Turnover & Vacancy Cost | G17: =G79 -> 421410 | J17: Turnover & Vacancy Cost | K17: =K79 -> 211410
B18: Total Cost Incl Turnover | C18: =C13+C17 -> 10737589 | F18: Total Cost Incl Turnover | G18: =G13+G17 -> 8624145.3 | J18: Total Cost Incl Turnover | K18: =K13+K17 -> 4100501.3
B19: Unit Service Volume | C19: =C37 -> 26280 | F19: Unit Service Volume | G19: =G37 -> 10402.5 | J19: Unit Service Volume | K19: =K32 -> 55000
B20: Cost/Service Unit | C20: =C64 -> 389.124 | F20: Cost/Service Unit | G20: =G64 -> 788.535 | J20: Cost/Service Unit | K20: =K64 -> 70.71075
B23: Baseline Inputs | F23: Baseline Inputs | J23: Baseline Inputs
B24: Wage multiplier | C24: ='Inputs & Scenarios'!C42 -> 1 | F24: Wage multiplier | G24: ='Inputs & Scenarios'!C42 -> 1 | J24: Wage multiplier | K24: ='Inputs & Scenarios'!C42 -> 1
B25: Volume/Occupancy multiplier | C25: ='Inputs & Scenarios'!C43 -> 1 | F25: Volume/Occupancy multiplier | G25: ='Inputs & Scenarios'!C43 -> 1 | J25: Volume/Occupancy multiplier | K25: ='Inputs & Scenarios'!C43 -> 1
B26: Staffing ratio multiplier | C26: ='Inputs & Scenarios'!C44 -> 1 | F26: Staffing ratio multiplier | G26: ='Inputs & Scenarios'!C44 -> 1 | J26: Staffing ratio multiplier | K26: ='Inputs & Scenarios'!C44 -> 1
B27: Agency % multiplier | C27: ='Inputs & Scenarios'!C45 -> 1 | F27: Agency % multiplier | G27: ='Inputs & Scenarios'!C45 -> 1 | J27: Agency % multiplier | K27: ='Inputs & Scenarios'!C45 -> 1
B28: Turnover multiplier | C28: ='Inputs & Scenarios'!C46 -> 1 | F28: Turnover multiplier | G28: ='Inputs & Scenarios'!C46 -> 1 | J28: Turnover multiplier | K28: ='Inputs & Scenarios'!C46 -> 1
B31: Operationa Drivers | F31: Operationa Drivers | J31: Operationa Drivers
B32: Beds | C32: ='Inputs & Scenarios'!C36 -> 80 | F32: Beds | G32: ='Inputs & Scenarios'!C37 -> 30 | J32: Ed Visits/yr | K32: ='Inputs & Scenarios'!H38 -> 55000
B33: Avg Occupancy | C33: ='Inputs & Scenarios'!D36 -> 0.9 | F33: Avg Occupancy | G33: ='Inputs & Scenarios'!D37 -> 0.95 | J33: RN Hours/ED Visit | K33: ='Inputs & Scenarios'!I38 -> 1.1
B34: Nurse-To-Patient Ratio | C34: ='Inputs & Scenarios'!E36*C26 -> 4 | F34: Nurse-To-Patient Ratio | G34: ='Inputs & Scenarios'!E37*G26 -> 2 | J34: Agency Hours % | K34: ='Inputs & Scenarios'!F38 -> 0.1
B35: Agency Hours % | C35: ='Inputs & Scenarios'!F36*C27 -> 0.12 | F35: Agency Hours % | G35: ='Inputs & Scenarios'!F37*Model!G27 -> 0.15 | J35: Core RN FTEs | K35: ='Inputs & Scenarios'!G38 -> 30
B36: Core RN FTEs | C36: ='Inputs & Scenarios'!G36 -> 80 | F36: Core RN FTEs | G36: ='Inputs & Scenarios'!G37*Model!G26 -> 65 | J36: Required RN Hours/yr | K36: =K32*K33 -> 60500
B37: Patient Days/Yr | C37: ='Inputs & Scenarios'!C36*'Inputs & Scenarios'!D36*365*C25 -> 26280 | F37: Patient Days/Yr | G37: ='Inputs & Scenarios'!C37*'Inputs & Scenarios'!D37*365*Model!G25 -> 10402.5
B38: RN Hours/Patient Day (HPPD) | C38: =24/C34 -> 6 | F38: RN Hours/Patient Day (HPPD) | G38: =24/G34 -> 12
B39: Required RN Hours/yr | C39: =C38*C37 -> 157680 | F39: Required RN Hours/yr | G39: =G38*G37 -> 124830
B42: Hours Mix (Regular vs OT vs Agency) | F42: Hours Mix (Regular vs OT vs Agency) | J42: Hours Mix (Regular vs OT vs Agency)
B43: Productive Hours/FTE | C43: ='Inputs & Scenarios'!$C$23 -> 1872 | F43: Productive Hours/FTE | G43: ='Inputs & Scenarios'!$C$23 -> 1872 | J43: Productive Hours/FTE | K43: ='Inputs & Scenarios'!$C$23 -> 1872
B44: Avilable Regular Hours | C44: =C43*C36 -> 149760 | F44: Avilable Regular Hours | G44: =G43*G36 -> 121680 | J44: Avilable Regular Hours | K44: =K43*K35 -> 56160
B45: Agencey Hours | C45: =C35*C39 -> 18921.6 | F45: Agencey Hours | G45: =G35*G39 -> 18724.5 | J45: Agencey Hours | K45: =K34*K36 -> 6050
B46: Core Hours (non-agency) | C46: =C39-C45 -> 138758.4 | F46: Core Hours (non-agency) | G46: =G39-G45 -> 106105.5 | J46: Core Hours (non-agency) | K46: =K36-K45 -> 54450
B47: Regulare Hours (Covered by CORE FTE) | C47: =MIN(C44,C46) -> 138758.4 | F47: Regulare Hours (Covered by CORE FTE) | G47: =MIN(G44,G46) -> 106105.5 | J47: Regulare Hours (Covered by CORE FTE) | K47: =MIN(K44,K46) -> 54450
B48: OT Hours | C48: =MAX(0,(C46-C44)) -> 0 | F48: OT Hours | G48: =MAX(0,(G46-G44)) -> 0 | J48: OT Hours | K48: =MAX(0,(K46-K44)) -> 0
B49: OT % of Total Hours | C49: =C48/C39 -> 0 | F49: OT % of Total Hours | G49: =G48/G39 -> 0 | J49: OT % of Total Hours | K49: =K48/K36 -> 0
B50: Agencey % of Total Hours | C50: =C45/C39 -> 0.12 | F50: Agencey % of Total Hours | G50: =G45/G39 -> 0.15 | J50: Agencey % of Total Hours | K50: =K45/K36 -> 0.1
B53: Cost Calculations | F53: Cost Calculations | J53: Cost Calculations
B54: Base Hourly Wage | C54: ='Inputs & Scenarios'!C18*C24 -> 45 | F54: Base Hourly Wage | G54: ='Inputs & Scenarios'!C18*G24 -> 45 | J54: Base Hourly Wage | K54: ='Inputs & Scenarios'!C18*K24 -> 45
B55: OT Hourly Wage | C55: =C54*'Inputs & Scenarios'!C19 -> 67.5 | F55: OT Hourly Wage | G55: =G54*'Inputs & Scenarios'!C19 -> 67.5 | J55: OT Hourly Wage | K55: =K54*'Inputs & Scenarios'!C19 -> 67.5
...

Sheet Inputs & Scenarios
B2: Secnarios & Inputs
B6: Model Control
B7: Scenario | C7: 1
B9: Scenario/Metric | C9: Wage multiplier | D9: Volume/Occupancy multiplier | E9: Staffing ratio multiplier | F9: Agency % multiplier | G9: Turnover multiplier
B10: Baseline | C10: 1 | D10: 1 | E10: 1 | F10: 1 | G10: 1
B11: Cost Control | C11: 0.98 | D11: 0.97 | E11: 1.05 | F11: 0.8 | G11: 0.95
B12: Quality Investment | C12: 1.05 | D12: 1.03 | E12: 0.95 | F12: 0.7 | G12: 0.85
B13: Stress Case | C13: 1.08 | D13: 1 | E13: 0.85 | F13: 1.3 | G13: 1.4
B14: Notes | C14: Applies to base | D14: Beds occ or ED visits | E14: Higher = fewer nurses per patient (worse) | F14: Lower = less agency | G14: Lower = better retention
B17: Pay Assumption
B18: Base RN Hourly wage ($/h) | C18: 45
B19: OT Myltiplier | C19: 1.5
B20: Agencey Horuly Rate ($/h) | C20: 90
B21: Benefit Load (% of Wages) | C21: 0.3
B22: Shift Differential (%add-on) | C22: 0.05
B23: Productive Hours/RN FTE (h/year) | C23: 1872
B26: Turnover & Vacancy Cost
B27: Annual RN Turnover Rate | C27: 0.15
B28: Replacement Cost/RN ($) | C28: 40000
B29: Vacancy Weeks/Hire | C29: 10
B30: % of Vacancy Hours Covered by Agenecey | C30: 0.4
B31: % of Vacancy Hours Covered by OT | C31: 0.6
B34: Unit Operational Assumptions
B35: Unit | C35: Beds | D35: Avg Occupancy | E35: Nurse--to-Patient Ratio | F35: Agencey Hours % | G35: RN FTEs (Core) | H35: ED Visits/yr | I35: RN Hours/ED Visits
B36: Med - Surg | C36: 80 | D36: 0.9 | E36: 4 | F36: 0.12 | G36: 80
B37: ICU | C37: 30 | D37: 0.95 | E37: 2 | F37: 0.15 | G37: 65
B38: ED | F38: 0.1 | G38: 30 | H38: 55000 | I38: 1.1
B41: Selected Cenario Multipliers
B42: Wage multiplier | C42: {=INDEX(C10:C13,$C$7)} -> 1
B43: Volume/Occupancy multiplier | C43: {=INDEX(D10:D13,$C$7)} -> 1
B44: Staffing ratio multiplier | C44: {=INDEX(E10:E13,$C$7)} -> 1
B45: Agency % multiplier | C45: {=INDEX(F10:F13,$C$7)} -> 1
B46: Turnover multiplier | C46: {=INDEX(G10:G13,$C$7)} -> 1
